<?xml version="1.0" encoding="utf-8"?>
<!-- This URDF was automatically created by SolidWorks to URDF Exporter! Originally created by Stephen Brawner (brawner@gmail.com) 
     Commit Version: 1.6.0-4-g7f85cfe  Build Version: 1.6.7995.38578
     For more information, please see http://wiki.ros.org/sw_urdf_exporter -->
<robot
  name="Assem2.SLDASM">
  <link
    name="Frame">
    <inertial>
      <origin
        xyz="-0.022104 0.011045 0.011664"
        rpy="0 0 0" />
      <mass
        value="0.025454" />
      <inertia
        ixx="2.5007E-05"
        ixy="-3.4539E-21"
        ixz="-4.6236E-20"
        iyy="3.4288E-05"
        iyz="1.2006E-20"
        izz="1.4426E-05" />
    </inertial>
    <visual>
      <origin
        xyz="0 0 0"
        rpy="0 0 0" />
      <geometry>
        <mesh
          filename="package://Assem2.SLDASM/meshes/Frame.STL" />
      </geometry>
      <material
        name="">
        <color
          rgba="0.79216 0.81961 0.93333 1" />
      </material>
    </visual>
    <collision>
      <origin
        xyz="0 0 0"
        rpy="0 0 0" />
      <geometry>
        <mesh
          filename="package://Assem2.SLDASM/meshes/Frame.STL" />
      </geometry>
    </collision>
  </link>
  <joint
    name="jfoot4"
    type="revolute">
    <origin
      xyz="0 -0.00105 -0.0525"
      rpy="-1.5708 -0.80198 0" />
    <parent
      link="leg4" />
    <child
      link="foot4" />
    <axis
      xyz="0 0 1" />
    <limit
      lower="-1.57"
      upper="1.57"
      effort="10"
      velocity="100" />
  </joint>
  <link
    name="leg1">
    <inertial>
      <origin
        xyz="2.0443E-06 0.012693 -0.019862"
        rpy="0 0 0" />
      <mass
        value="0.01231" />
      <inertia
        ixx="6.0888E-06"
        ixy="-4.6836E-11"
        ixz="6.8968E-10"
        iyy="5.3316E-06"
        iyz="8.0165E-08"
        izz="1.9379E-06" />
    </inertial>
    <visual>
      <origin
        xyz="0 0 0"
        rpy="0 0 0" />
      <geometry>
        <mesh
          filename="package://Assem2.SLDASM/meshes/leg1.STL" />
      </geometry>
      <material
        name="">
        <color
          rgba="1 0.93725 0.13725 1" />
      </material>
    </visual>
    <collision>
      <origin
        xyz="0 0 0"
        rpy="0 0 0" />
      <geometry>
        <mesh
          filename="package://Assem2.SLDASM/meshes/leg1.STL" />
      </geometry>
    </collision>
  </link>
  <joint
    name="jleg1"
    type="revolute">
    <origin
      xyz="0.016946 0.024039 -0.0053426"
      rpy="0 -1.3468 -1.5708" />
    <parent
      link="Frame" />
    <child
      link="leg1" />
    <axis
      xyz="0 1 0" />
    <limit
      lower="-1.57"
      upper="1.57"
      effort="10"
      velocity="100" />
  </joint>
  <link
    name="foot1">
    <inertial>
      <origin
        xyz="0.000242245303306736 -0.00820894363230492 -0.00516291752319666"
        rpy="0 0 0" />
      <mass
        value="0.00392629259448471" />
      <inertia
        ixx="9.19094740755393E-07"
        ixy="1.83225309328215E-08"
        ixz="7.96099068083954E-10"
        iyy="1.72711871161383E-07"
        iyz="-2.61744786760478E-08"
        izz="1.05601132952815E-06" />
    </inertial>
    <visual>
      <origin
        xyz="0 0 0"
        rpy="0 0 0" />
      <geometry>
        <mesh
          filename="package://Assem2.SLDASM/meshes/foot1.STL" />
      </geometry>
      <material
        name="">
        <color
          rgba="0.286274509803922 0.662745098039216 0.329411764705882 1" />
      </material>
    </visual>
    <collision>
      <origin
        xyz="0 0 0"
        rpy="0 0 0" />
      <geometry>
        <mesh
          filename="package://Assem2.SLDASM/meshes/foot1.STL" />
      </geometry>
    </collision>
  </link>
  <joint
    name="jfoot1"
    type="revolute">
    <origin
      xyz="0 -0.00105 -0.0525"
      rpy="-1.5708 -0.91499 0" />
    <parent
      link="leg1" />
    <child
      link="foot1" />
    <axis
      xyz="0 0 1" />
    <limit
      lower="-1.57"
      upper="1.57"
      effort="10"
      velocity="100" />
  </joint>
  <link
    name="leg2">
    <inertial>
      <origin
        xyz="2.3973E-06 0.012693 -0.019862"
        rpy="0 0 0" />
      <mass
        value="0.012311" />
      <inertia
        ixx="6.0889E-06"
        ixy="-7.4211E-12"
        ixz="7.563E-10"
        iyy="5.3318E-06"
        iyz="8.0119E-08"
        izz="1.9379E-06" />
    </inertial>
    <visual>
      <origin
        xyz="0 0 0"
        rpy="0 0 0" />
      <geometry>
        <mesh
          filename="package://Assem2.SLDASM/meshes/leg2.STL" />
      </geometry>
      <material
        name="">
        <color
          rgba="1 0.93725 0.13725 1" />
      </material>
    </visual>
    <collision>
      <origin
        xyz="0 0 0"
        rpy="0 0 0" />
      <geometry>
        <mesh
          filename="package://Assem2.SLDASM/meshes/leg2.STL" />
      </geometry>
    </collision>
  </link>
  <joint
    name="jleg2"
    type="revolute">
    <origin
      xyz="-0.061154 0.024039 -0.0053426"
      rpy="0 1.3468 1.5708" />
    <parent
      link="Frame" />
    <child
      link="leg2" />
    <axis
      xyz="0 1 0" />
    <limit
      lower="-1.57"
      upper="1.57"
      effort="10"
      velocity="100" />
  </joint>
  <link
    name="foot2">
    <inertial>
      <origin
        xyz="0.00024225 -0.0082089 -0.0051629"
        rpy="0 0 0" />
      <mass
        value="0.0039263" />
      <inertia
        ixx="9.1909E-07"
        ixy="1.8323E-08"
        ixz="7.961E-10"
        iyy="1.7271E-07"
        iyz="-2.6174E-08"
        izz="1.056E-06" />
    </inertial>
    <visual>
      <origin
        xyz="0 0 0"
        rpy="0 0 0" />
      <geometry>
        <mesh
          filename="package://Assem2.SLDASM/meshes/foot2.STL" />
      </geometry>
      <material
        name="">
        <color
          rgba="0.28627 0.66275 0.32941 1" />
      </material>
    </visual>
    <collision>
      <origin
        xyz="0 0 0"
        rpy="0 0 0" />
      <geometry>
        <mesh
          filename="package://Assem2.SLDASM/meshes/foot2.STL" />
      </geometry>
    </collision>
  </link>
  <joint
    name="jfoot2"
    type="revolute">
    <origin
      xyz="0 -0.00105 -0.0525"
      rpy="-1.5708 0.91499 0" />
    <parent
      link="leg2" />
    <child
      link="foot2" />
    <axis
      xyz="0 0 1" />
    <limit
      lower="-1.57"
      upper="1.57"
      effort="10"
      velocity="100" />
  </joint>
  <link
    name="leg3">
    <inertial>
      <origin
        xyz="2.4083E-06 0.012693 -0.019862"
        rpy="0 0 0" />
      <mass
        value="0.012311" />
      <inertia
        ixx="6.0889E-06"
        ixy="-7.3083E-12"
        ixz="7.5758E-10"
        iyy="5.3318E-06"
        iyz="8.0119E-08"
        izz="1.9379E-06" />
    </inertial>
    <visual>
      <origin
        xyz="0 0 0"
        rpy="0 0 0" />
      <geometry>
        <mesh
          filename="package://Assem2.SLDASM/meshes/leg3.STL" />
      </geometry>
      <material
        name="">
        <color
          rgba="1 0.93725 0.13725 1" />
      </material>
    </visual>
    <collision>
      <origin
        xyz="0 0 0"
        rpy="0 0 0" />
      <geometry>
        <mesh
          filename="package://Assem2.SLDASM/meshes/leg3.STL" />
      </geometry>
    </collision>
  </link>
  <joint
    name="jleg3"
    type="revolute">
    <origin
      xyz="-0.061154 -0.047367 -0.0053426"
      rpy="0 1.492 1.5708" />
    <parent
      link="Frame" />
    <child
      link="leg3" />
    <axis
      xyz="0 1 0" />
    <limit
      lower="-1.57"
      upper="1.57"
      effort="10"
      velocity="100" />
  </joint>
  <link
    name="foot3">
    <inertial>
      <origin
        xyz="0.00024225 -0.0082089 -0.0051629"
        rpy="0 0 0" />
      <mass
        value="0.0039263" />
      <inertia
        ixx="9.1909E-07"
        ixy="1.8323E-08"
        ixz="7.961E-10"
        iyy="1.7271E-07"
        iyz="-2.6174E-08"
        izz="1.056E-06" />
    </inertial>
    <visual>
      <origin
        xyz="0 0 0"
        rpy="0 0 0" />
      <geometry>
        <mesh
          filename="package://Assem2.SLDASM/meshes/foot3.STL" />
      </geometry>
      <material
        name="">
        <color
          rgba="0.28627 0.66275 0.32941 1" />
      </material>
    </visual>
    <collision>
      <origin
        xyz="0 0 0"
        rpy="0 0 0" />
      <geometry>
        <mesh
          filename="package://Assem2.SLDASM/meshes/foot3.STL" />
      </geometry>
    </collision>
  </link>
  <joint
    name="jfoot3"
    type="revolute">
    <origin
      xyz="0 -0.00105 -0.0525"
      rpy="-1.5708 0.80198 0" />
    <parent
      link="leg3" />
    <child
      link="foot3" />
    <axis
      xyz="0 0 1" />
    <limit
      lower="-1.57"
      upper="1.57"
      effort="10"
      velocity="100" />
  </joint>
  <link
    name="leg4">
    <inertial>
      <origin
        xyz="1.9805E-06 0.012693 -0.019862"
        rpy="0 0 0" />
      <mass
        value="0.01231" />
      <inertia
        ixx="6.0888E-06"
        ixy="-4.6687E-11"
        ixz="6.8404E-10"
        iyy="5.3316E-06"
        iyz="8.0164E-08"
        izz="1.9378E-06" />
    </inertial>
    <visual>
      <origin
        xyz="0 0 0"
        rpy="0 0 0" />
      <geometry>
        <mesh
          filename="package://Assem2.SLDASM/meshes/leg4.STL" />
      </geometry>
      <material
        name="">
        <color
          rgba="1 0.93725 0.13725 1" />
      </material>
    </visual>
    <collision>
      <origin
        xyz="0 0 0"
        rpy="0 0 0" />
      <geometry>
        <mesh
          filename="package://Assem2.SLDASM/meshes/leg4.STL" />
      </geometry>
    </collision>
  </link>
  <joint
    name="jleg4"
    type="revolute">
    <origin
      xyz="0.016946 -0.047367 -0.0053426"
      rpy="0 -1.492 -1.5708" />
    <parent
      link="Frame" />
    <child
      link="leg4" />
    <axis
      xyz="0 1 0" />
    <limit
      lower="-1.57"
      upper="1.57"
      effort="10"
      velocity="100" />
  </joint>
  <link
    name="foot4">
    <inertial>
      <origin
        xyz="0.00024225 -0.0082089 -0.0051629"
        rpy="0 0 0" />
      <mass
        value="0.0039263" />
      <inertia
        ixx="9.1909E-07"
        ixy="1.8323E-08"
        ixz="7.961E-10"
        iyy="1.7271E-07"
        iyz="-2.6174E-08"
        izz="1.056E-06" />
    </inertial>
    <visual>
      <origin
        xyz="0 0 0"
        rpy="0 0 0" />
      <geometry>
        <mesh
          filename="package://Assem2.SLDASM/meshes/foot4.STL" />
      </geometry>
      <material
        name="">
        <color
          rgba="0.28627 0.66275 0.32941 1" />
      </material>
    </visual>
    <collision>
      <origin
        xyz="0 0 0"
        rpy="0 0 0" />
      <geometry>
        <mesh
          filename="package://Assem2.SLDASM/meshes/foot4.STL" />
      </geometry>
    </collision>
  </link>
  <joint
    name="jfoot4"
    type="revolute">
    <origin
      xyz="0 -0.00105 -0.0525"
      rpy="-1.5708 -0.80198 0" />
    <parent
      link="leg4" />
    <child
      link="foot4" />
    <axis
      xyz="0 0 1" />
    <limit
      lower="-1.57"
      upper="1.57"
      effort="10"
      velocity="100" />
  </joint>
</robot>